  File "C:\Users\Mrmr\Desktop\BINANCE\.venv\Lib\site-packages\httpcore\_async\http11.py", line 250, in _response_closed
    await self.aclose()
  File "C:\Users\Mrmr\Desktop\BINANCE\.venv\Lib\site-packages\httpcore\_async\http11.py", line 258, in aclose
    await self._network_stream.aclose()
  File "C:\Users\Mrmr\Desktop\BINANCE\.venv\Lib\site-packages\httpcore\_backends\anyio.py", line 53, in aclose
    await self._stream.aclose()
  File "C:\Users\Mrmr\Desktop\BINANCE\.venv\Lib\site-packages\anyio\streams\tls.py", line 201, in aclose
    await self.transport_stream.aclose()
  File "C:\Users\Mrmr\Desktop\BINANCE\.venv\Lib\site-packages\anyio\_backends\_asyncio.py", line 1287, in aclose
    self._transport.close()
  File "C:\Program Files\WindowsApps\PythonSoftwareFoundation.Python.3.11_3.11.2544.0_x64__qbz5n2kfra8p0\Lib\asyncio\proactor_events.py", line 109, in close
    self._loop.call_soon(self._call_connection_lost, None)
  File "C:\Program Files\WindowsApps\PythonSoftwareFoundation.Python.3.11_3.11.2544.0_x64__qbz5n2kfra8p0\Lib\asyncio\base_events.py", line 762, in call_soon
    self._check_closed()
  File "C:\Program Files\WindowsApps\PythonSoftwareFoundation.Python.3.11_3.11.2544.0_x64__qbz5n2kfra8p0\Lib\asyncio\base_events.py", line 520, in _check_closed
    raise RuntimeError('Event loop is closed')
RuntimeError: Event loop is closed

The above exception was the direct cause of the following exception:

Traceback (most recent call last):
  File "C:\Users\Mrmr\Desktop\BINANCE\.venv\Lib\site-packages\telegram\ext\_application.py", line 1319, in process_update
    await coroutine
  File "C:\Users\Mrmr\Desktop\BINANCE\.venv\Lib\site-packages\telegram\ext\_handlers\basehandler.py", line 158, in handle_update    
    return await self.callback(update, context)
           ^^^^^^^^^^^^^^^^^^^^^^^^^^^^^^^^^^^^
  File "c:\Users\Mrmr\Desktop\BINANCE\telegram_notifier.py", line 42, in cmd_help
    await update.message.reply_text(
  File "C:\Users\Mrmr\Desktop\BINANCE\.venv\Lib\site-packages\telegram\_message.py", line 1771, in reply_text
    return await self.get_bot().send_message(
           ^^^^^^^^^^^^^^^^^^^^^^^^^^^^^^^^^^
  File "C:\Users\Mrmr\Desktop\BINANCE\.venv\Lib\site-packages\telegram\ext\_extbot.py", line 2965, in send_message
    return await super().send_message(
           ^^^^^^^^^^^^^^^^^^^^^^^^^^^
  File "C:\Users\Mrmr\Desktop\BINANCE\.venv\Lib\site-packages\telegram\_bot.py", line 1019, in send_message
    return await self._send_message(
           ^^^^^^^^^^^^^^^^^^^^^^^^^
  File "C:\Users\Mrmr\Desktop\BINANCE\.venv\Lib\site-packages\telegram\ext\_extbot.py", line 610, in _send_message
    result = await super()._send_message(
             ^^^^^^^^^^^^^^^^^^^^^^^^^^^^
  File "C:\Users\Mrmr\Desktop\BINANCE\.venv\Lib\site-packages\telegram\_bot.py", line 731, in _send_message
    result = await self._post(
             ^^^^^^^^^^^^^^^^^
  File "C:\Users\Mrmr\Desktop\BINANCE\.venv\Lib\site-packages\telegram\_bot.py", line 619, in _post
    return await self._do_post(
           ^^^^^^^^^^^^^^^^^^^^
  File "C:\Users\Mrmr\Desktop\BINANCE\.venv\Lib\site-packages\telegram\ext\_extbot.py", line 354, in _do_post
    return await super()._do_post(
           ^^^^^^^^^^^^^^^^^^^^^^^
  File "C:\Users\Mrmr\Desktop\BINANCE\.venv\Lib\site-packages\telegram\_bot.py", line 648, in _do_post
    result = await request.post(
             ^^^^^^^^^^^^^^^^^^^
  File "C:\Users\Mrmr\Desktop\BINANCE\.venv\Lib\site-packages\telegram\request\_baserequest.py", line 202, in post
    result = await self._request_wrapper(
             ^^^^^^^^^^^^^^^^^^^^^^^^^^^^
  File "C:\Users\Mrmr\Desktop\BINANCE\.venv\Lib\site-packages\telegram\request\_baserequest.py", line 346, in _request_wrapper      
    raise NetworkError(f"Unknown error in HTTP implementation: {exc!r}") from exc
telegram.error.NetworkError: Unknown error in HTTP implementation: RuntimeError('Event loop is closed')
Mesaj gönderme hatası: Unknown error in HTTP implementation: RuntimeError('Event loop is closed')
Mesaj gönderme hatası: Unknown error in HTTP implementation: RuntimeError('<asyncio.locks.Event object at 0x000001A315C83310 [unset]> is bound to a different event loop')
Mesaj gönderme hatası: Unknown error in HTTP implementation: RuntimeError('Event loop is closed')
Mesaj gönderme hatası: Unknown error in HTTP implementation: RuntimeError('Event loop is closed')
Mesaj gönderme hatası: Unknown error in HTTP implementation: RuntimeError('Event loop is closed')
Mesaj gönderme hatası: Unknown error in HTTP implementation: RuntimeError('Event loop is closed')
Mesaj gönderme hatası: Unknown error in HTTP implementation: RuntimeError('<asyncio.locks.Event object at 0x000001A31DA4C990 [unset]> is bound to a different event loop')
Mesaj gönderme hatası: Unknown error in HTTP implementation: RuntimeError('Event loop is closed')